Workbook

Sheet BP
A1: Vasco SAF — Balanço Patrimonial Consolidado
A2: R$ mil | 2023 reapresentado conforme ITG 2003 (R2)
A4: Linha | B4: 2023 reapr. | C4: 2024 | D4: 2025 | E4: Δ 25 vs 24 | F4: Notas
A5: ATIVO
A6: Circulante
A7: Caixa e equivalentes | B7: 79926 | C7: 28504 | D7: 60344 | E7: =IFERROR((D7-C7)/ABS(C7),"") -> 1.1170362
A8: Contas a receber | B8: 74426 | C8: 127836 | D8: 83339 | E8: =IFERROR((D8-C8)/ABS(C8),"") -> -0.34807879
A9: Créditos com partes relacionadas | B9: 10850 | C9: 29954 | D9: 24914 | E9: =IFERROR((D9-C9)/ABS(C9),"") -> -0.168258
A10: Estoques | B10: 1017 | C10: 1075 | D10: 3837 | E10: =IFERROR((D10-C10)/ABS(C10),"") -> 2.5693023
A11: Adiantamentos a terceiros | B11: 1624 | C11: 3238 | D11: 5665 | E11: =IFERROR((D11-C11)/ABS(C11),"") -> 0.74953675
A12: Despesas antecipadas | B12: 4114 | C12: 681 | D12: 817 | E12: =IFERROR((D12-C12)/ABS(C12),"") -> 0.19970631
A13: Impostos a recuperar | B13: 116 | C13: 121 | D13: 591 | E13: =IFERROR((D13-C13)/ABS(C13),"") -> 3.8842975
A14: Outros ativos | B14: 342 | C14: 344 | D14: 534 | E14: =IFERROR((D14-C14)/ABS(C14),"") -> 0.55232558
A15: Total ativo circulante | B15: =SUM(B7:B14) -> 172415 | C15: =SUM(C7:C14) -> 191753 | D15: =SUM(D7:D14) -> 180041 | E15: =IFERROR((D15-C15)/ABS(C15),"") -> -0.061078575
A16: Não circulante
A17: Contas a receber | B17: 4321 | C17: 469 | D17: 15170 | E17: =IFERROR((D17-C17)/ABS(C17),"") -> 31.345416
A18: Despesas antecipadas | B18: 4065 | C18: 6196 | D18: 5949 | E18: =IFERROR((D18-C18)/ABS(C18),"") -> -0.039864429
A19: Depósitos judiciais | B19: 28303 | C19: 28769 | D19: 25631 | E19: =IFERROR((D19-C19)/ABS(C19),"") -> -0.10907574
A20: Créditos tributários | B20: 32073 | C20: 32073 | D20: 30251 | E20: =IFERROR((D20-C20)/ABS(C20),"") -> -0.056807907
A21: Imobilizado | B21: 28147 | C21: 27686 | D21: 30261 | E21: =IFERROR((D21-C21)/ABS(C21),"") -> 0.093007296
A22: Intangível (atletas) | B22: 119922 | C22: 189231 | D22: 161505 | E22: =IFERROR((D22-C22)/ABS(C22),"") -> -0.14651933
A23: Total ativo não circulante | B23: =SUM(B17:B22) -> 216831 | C23: =SUM(C17:C22) -> 284424 | D23: =SUM(D17:D22) -> 268767 | E23: =IFERROR((D23-C23)/ABS(C23),"") -> -0.055048097
A24: TOTAL DO ATIVO | B24: =B15+B23 -> 389246 | C24: =C15+C23 -> 476177 | D24: =D15+D23 -> 448808 | E24: =IFERROR((D24-C24)/ABS(C24),"") -> -0.057476527
A26: PASSIVO
A27: Circulante
A28: Fornecedores | B28: 38514 | C28: 58801 | D28: 53334 | E28: =IFERROR((D28-C28)/ABS(C28),"") -> -0.092974609
A29: Obrigações trabalhistas e sociais | B29: 20515 | C29: 27684 | D29: 30429 | E29: =IFERROR((D29-C29)/ABS(C29),"") -> 0.099154746
A30: Impostos a recolher | B30: 19307 | C30: 26176 | D30: 18927 | E30: =IFERROR((D30-C30)/ABS(C30),"") -> -0.27693307
A31: Imagem e transações de atletas a pagar | B31: 110311 | C31: 198541 | D31: 112992 | E31: =IFERROR((D31-C31)/ABS(C31),"") -> -0.43088833
A32: Regime Centralizado de Execuções (RCE) | B32: 65990 | C32: 30001 | D32: 0 | E32: =IFERROR((D32-C32)/ABS(C32),"") -> -1
A33: Parcelamentos | B33: 34610 | C33: 49868 | D33: 73031 | E33: =IFERROR((D33-C33)/ABS(C33),"") -> 0.46448624
A34: Obrigações com entidades esportivas | B34: 13346 | C34: 7993 | D34: 2004 | E34: =IFERROR((D34-C34)/ABS(C34),"") -> -0.74928062
A35: Empréstimos e financiamentos | B35: 44408 | C35: 4330 | D35: 32517 | E35: =IFERROR((D35-C35)/ABS(C35),"") -> 6.5096998
A36: Arrendamentos | B36: 1001 | C36: 227 | D36: 16585 | E36: =IFERROR((D36-C36)/ABS(C36),"") -> 72.061674
A37: Passivo contratual | B37: 13380 | C37: 44634 | D37: 28555 | E37: =IFERROR((D37-C37)/ABS(C37),"") -> -0.36024107
A38: Acordos cíveis e trabalhistas | B38: 1626 | C38: 13601 | D38: 4976 | E38: =IFERROR((D38-C38)/ABS(C38),"") -> -0.63414455
A39: Provisão para riscos judiciais | B39: 8420 | C39: 8413 | D39: 0 | E39: =IFERROR((D39-C39)/ABS(C39),"") -> -1
A40: Passivo Concursal — RJ (circ.) | B40: 0 | C40: 0 | D40: 11155 | E40: =IFERROR((D40-C40)/ABS(C40),"")
A41: Total passivo circulante | B41: =SUM(B28:B40) -> 371428 | C41: =SUM(C28:C40) -> 470269 | D41: =SUM(D28:D40) -> 384505 | E41: =IFERROR((D41-C41)/ABS(C41),"") -> -0.18237222
A42: Não circulante
...

Sheet DRE
A1: Vasco SAF — Demonstração do Resultado
A2: R$ mil | 2023 reapresentado conforme ITG 2003 (R2)
A4: Linha | B4: 2023 reapr. | C4: 2024 | D4: 2025 | E4: Δ 25 vs 24 | F4: Notas
A5: Receita operacional líquida | B5: 222091 | C5: 282340 | D5: 413878 | E5: =IFERROR((D5-C5)/ABS(C5),"") -> 0.4658851
A6: Custos operacionais | B6: -293803 | C6: -382141 | D6: -541302 | E6: =IFERROR((D6-C6)/ABS(C6),"") -> -0.4164981
A7: Resultado bruto | B7: =B5+B6 -> -71712 | C7: =C5+C6 -> -99801 | D7: =D5+D6 -> -127424 | E7: =IFERROR((D7-C7)/ABS(C7),"") -> -0.27678079
A8: Despesas gerais e administrativas | B8: -75845 | C8: -52914 | D8: -155942 | E8: =IFERROR((D8-C8)/ABS(C8),"") -> -1.9470839
A9: Outras receitas/(despesas) operacionais | B9: 77064 | C9: 96125 | D9: 156894 | E9: =IFERROR((D9-C9)/ABS(C9),"") -> 0.63218726 | F9: 2025: inclui ~R$ 114,3 M de deságios da RJ (Nota 29.ii)
A10: Resultado operacional antes do financeiro | B10: =B7+B8+B9 -> -70493 | C10: =C7+C8+C9 -> -56590 | D10: =D7+D8+D9 -> -126472 | E10: =IFERROR((D10-C10)/ABS(C10),"") -> -1.2348825
A11: Despesas financeiras | B11: -68650 | C11: -75795 | D11: -105308 | E11: =IFERROR((D11-C11)/ABS(C11),"") -> -0.38937925
A12: Receitas financeiras | B12: 14575 | C12: 17702 | D12: 312998 | E12: =IFERROR((D12-C12)/ABS(C12),"") -> 16.681505 | F12: 2025: R$ 293,2 M de "descontos obtidos" = deságios da RJ (Nota 30)
A13: Resultado financeiro líquido | B13: =B11+B12 -> -54075 | C13: =C11+C12 -> -58093 | D13: =D11+D12 -> 207690 | E13: =IFERROR((D13-C13)/ABS(C13),"") -> 4.5751295
A14: Lucro/(Prejuízo) do exercício | B14: =B10+B13 -> -124568 | C14: =C10+C13 -> -114683 | D14: =D10+D13 -> 81218 | E14: =IFERROR((D14-C14)/ABS(C14),"") -> 1.7081956
A16: MARGENS
A17: Margem bruta | B17: =B7/B5 -> -0.32289467 | C17: =C7/C5 -> -0.35347808 | D17: =D7/D5 -> -0.30787817 | E17: =IFERROR((D17-C17)/ABS(C17),"") -> 0.1290035
A18: Margem operacional | B18: =B10/B5 -> -0.31740593 | C18: =C10/C5 -> -0.2004321 | D18: =D10/D5 -> -0.30557797 | E18: =IFERROR((D18-C18)/ABS(C18),"") -> -0.52459595
A19: Margem líquida | B19: =B14/B5 -> -0.5608872 | C19: =C14/C5 -> -0.40618758 | D19: =D14/D5 -> 0.19623657 | E19: =IFERROR((D19-C19)/ABS(C19),"") -> 1.4831181
A21: Notas:
A22: • A reapresentação de 2023 (ITG 2003 R2) reclassificou vendas de atletas da Receita Operacional para "Outras Receitas Operacionais".
A23: • Em 2025, dos R$ 156,9 M em "Outras receitas operacionais", ~R$ 114,3 M são deságios da RJ — não relacionados à operação.
A24: • Em 2025, das R$ 313 M em receitas financeiras, R$ 293,2 M são "descontos obtidos" via PRJ — também deságios contábeis sem caixa.
A25: • O lucro de R$ 81,2 M em 2025 é integralmente atribuível aos efeitos contábeis da homologação da RJ.

Sheet Receita Detalhada
A1: Vasco SAF — Composição da Receita por Categoria
A2: R$ mil | Nota 25 (2023 reapr.) | Nota 26 (2024 e 2025)
A4: Categoria | B4: 2023 reapr. | C4: 2024 | D4: 2025 | E4: Δ 25 vs 24 | F4: Natureza
A5: RECEITA OPERACIONAL BRUTA
A6: Direitos de transmissão | B6: 98697 | C6: 95133 | D6: 147061 | E6: =IFERROR((D6-C6)/ABS(C6),"") -> 0.54584634 | F6: Recorrente caixa (mas inclui apropriação histórica)
A7: Bilheteria | B7: 27412 | C7: 34227 | D7: 49947 | E7: =IFERROR((D7-C7)/ABS(C7),"") -> 0.45928653 | F7: Recorrente caixa
A8: Marketing/patrocínio | B8: 48982 | C8: 52999 | D8: 108207 | E8: =IFERROR((D8-C8)/ABS(C8),"") -> 1.04168 | F8: Recorrente caixa
A9: Programa sócio torcedor | B9: 31798 | C9: 53568 | D9: 46574 | E9: =IFERROR((D9-C9)/ABS(C9),"") -> -0.13056302 | F9: Recorrente caixa
A10: Tour da Colina | B10: 988 | C10: 1723 | D10: 1415 | E10: =IFERROR((D10-C10)/ABS(C10),"") -> -0.17875798 | F10: Recorrente caixa
A11: Receitas com premiação | B11: 19838 | C11: 51682 | D11: 65860 | E11: =IFERROR((D11-C11)/ABS(C11),"") -> 0.27433149 | F11: Recorrente caixa
A12: Licenciamento e royalties | B12: 8640 | C12: 6908 | D12: 9036 | E12: =IFERROR((D12-C12)/ABS(C12),"") -> 0.30804864 | F12: Recorrente caixa
A13: Venda de jogos | B13: 0 | C13: 0 | D13: 8695 | E13: =IFERROR((D13-C13)/ABS(C13),"") | F13: Recorrente caixa (novo em 2025)
A14: Receitas diversas | B14: 4059 | C14: 7648 | D14: 10970 | E14: =IFERROR((D14-C14)/ABS(C14),"") -> 0.43436192 | F14: Recorrente
A15: Total receita operacional bruta | B15: =SUM(B6:B14) -> 240414 | C15: =SUM(C6:C14) -> 303888 | D15: =SUM(D6:D14) -> 447765 | E15: =IFERROR((D15-C15)/ABS(C15),"") -> 0.47345404
A16: (-) Deduções (impostos e outras) | B16: -18323 | C16: -21548 | D16: -32471 | E16: =IFERROR((D16-C16)/ABS(C16),"") -> -0.50691479
A17: Receita operacional líquida | B17: =B15+B16 -> 222091 | C17: =C15+C16 -> 282340 | D17: =D15+D16 -> 415294 | E17: =IFERROR((D17-C17)/ABS(C17),"") -> 0.47090033
A19: TRANSAÇÕES DE ATLETAS (Outras Receitas Operacionais)
A20: Receita com transação de atletas | B20: 127181 | C20: 170258 | D20: 123866 | E20: =IFERROR((D20-C20)/ABS(C20),"") -> -0.27248059 | F20: Não-recorrente / windfall
A21: Custo com transação de atletas | B21: -48981 | C21: -74826 | D21: -81257 | E21: =IFERROR((D21-C21)/ABS(C21),"") -> -0.085946062 | F21: Custo direto da venda
A22: Outras receitas e despesas | B22: -1136 | C22: 694 | D22: 114285 | E22: =IFERROR((D22-C22)/ABS(C22),"") -> 163.67579 | F22: 2025: deságios RJ alocados nesta linha (Nota 29.ii)
A23: Total Outras Receitas Operacionais | B23: 77064 | C23: 96125 | D23: 156894 | E23: =IFERROR((D23-C23)/ABS(C23),"") -> 0.63218726
A25: DECOMPOSIÇÃO POR NATUREZA ECONÔMICA
A26: Receita recorrente caixa estimada (líquida) | B26: =(B6+B7+B8+B9+B10+B11+B12+B13+B14-55461)*B17/B15 -> 170856.92 | C26: =(C6+C7+C8+C9+C10+C11+C12+C13+C14)*C17/C15 -> 282340 | D26: =(D6+D7+D8+D9+D10+D11+D12+D13+D14)*D17/D15 -> 415294 | E26: =IFERROR((D26-C26)/ABS(C26),"") -> 0.47090033 | F26: 2023: deduzido R$ 55,5 M de apropriação luvas Globo 2016 (não-caixa). Aplicada dedução tributária proporcional.
A27: Apropriação não-caixa (luvas Globo 2016) | B27: 55461 | C27: 0 | D27: 0 | E27: =IFERROR((D27-C27)/ABS(C27),"")
A28: Ganho líquido com venda de atletas | B28: =B20+B21 -> 78200 | C28: =C20+C21 -> 95432 | D28: =D20+D21 -> 42609 | E28: =IFERROR((D28-C28)/ABS(C28),"") -> -0.55351454
A29: Deságios da RJ (não-caixa, contábil) | B29: 0 | C29: 0 | D29: 114285 | E29: =IFERROR((D29-C29)/ABS(C29),"")
A31: PARTICIPAÇÃO % DA RECEITA RECORRENTE CAIXA NO TOTAL
A32: Receita recorrente caixa / Receita total bruta + venda atletas | B32: =B26/(B15+B22) -> 0.71405196 | C32: =C26/(C15+C22) -> 0.92697533 | D32: =D26/(D15+D22) -> 0.73889156 | E32: =IFERROR((D32-C32)/ABS(C32),"") -> -0.20290052
A34: Notas:
A35: • Em 2023, dos R$ 98,7 M de "Direitos de transmissão", ~R$ 55,5 M são amortização das luvas Globo de 2016 (Nota 20 do BP 2023). Não geraram caixa em 2023.
A36: • Em 2024, o contrato de luvas Globo 2016 foi exaurido — última apropriação ocorreu naquele ano.
A37: • Em 2025, a LFF começou a ser apropriada como receita, em ritmo de 50 anos (~R$ 4 M/ano sobre os R$ 212,1 M brutos).
A38: • "Sócio torcedor" caiu 13% em 2025 vs 2024 — único item recorrente em queda.
A39: • "Marketing/patrocínio" mais que dobrou em 2025 vs 2024, refletindo reestruturação comercial pós-saída da 777.
A40: • Os R$ 114,3 M de "deságios da RJ" em 2025 não são receita operacional — são reconhecimento contábil de redução de passivo concursal.

Sheet DFC
A1: Vasco SAF — Demonstração de Fluxo de Caixa
A2: R$ mil | 2023 reapresentado | método indireto
A4: Linha | B4: 2023 reapr. | C4: 2024 | D4: 2025 | E4: Δ 25 vs 24 | F4: Notas
A5: ATIVIDADES OPERACIONAIS
A6: Lucro/(Prejuízo) do exercício | B6: -124568 | C6: -114682 | D6: 81218 | E6: =IFERROR((D6-C6)/ABS(C6),"") -> 1.7082018
A7: Ajustes não-caixa:
A8: Amortização direitos sobre atletas | B8: 58783 | C8: 92344 | D8: 125811 | E8: =IFERROR((D8-C8)/ABS(C8),"") -> 0.36241662
A9: Baixa de atletas | B9: 31479 | C9: 18567 | D9: 58492 | E9: =IFERROR((D9-C9)/ABS(C9),"") -> 2.1503205
A10: Encargos financeiros e juros | B10: -4943 | C10: 0 | D10: 0 | E10: =IFERROR((D10-C10)/ABS(C10),"")
A11: Juros e multas sobre fornecedores | B11: -4288 | C11: 5704 | D11: 2613 | E11: =IFERROR((D11-C11)/ABS(C11),"") -> -0.54190042
A12: Provisões para contingências | B12: 6495 | C12: 9634 | D12: 69092 | E12: =IFERROR((D12-C12)/ABS(C12),"") -> 6.1716836
A13: Depreciação imobilizado e amortização intangível | B13: 2614 | C13: 2987 | D13: 3443 | E13: =IFERROR((D13-C13)/ABS(C13),"") -> 0.15266153
A14: Despesa de juros | B14: 34847 | C14: 4938 | D14: 8442 | E14: =IFERROR((D14-C14)/ABS(C14),"") -> 0.70959903
A15: PECLD | B15: -20 | C15: -17123 | D15: 31092 | E15: =IFERROR((D15-C15)/ABS(C15),"") -> 2.8158033 | F15: O ganho de R$ 257,7 M no resultado é não-caixa (revertido aqui)
A16: AVP da Recuperação Judicial | B16: 0 | C16: 0 | D16: -257707 | E16: =IFERROR((D16-C16)/ABS(C16),"")
A17: Variação cambial e atualização monetária | B17: 14444 | C17: 30733 | D17: 73251 | E17: =IFERROR((D17-C17)/ABS(C17),"") -> 1.383464
A18: Subtotal ajustes não-caixa | B18: =SUM(B8:B17) -> 139411 | C18: =SUM(C8:C17) -> 147784 | D18: =SUM(D8:D17) -> 114529 | E18: =IFERROR((D18-C18)/ABS(C18),"") -> -0.22502436
A19: Variações de capital de giro:
A20: Contas a receber | B20: -50327 | C20: -32435 | D20: -1297 | E20: =IFERROR((D20-C20)/ABS(C20),"") -> 0.96001233
A21: Estoques | B21: -92 | C21: -58 | D21: -2762 | E21: =IFERROR((D21-C21)/ABS(C21),"") -> -46.62069
A22: Adiantamentos a terceiros | B22: -900 | C22: -1614 | D22: -2427 | E22: =IFERROR((D22-C22)/ABS(C22),"") -> -0.50371747
A23: Despesas antecipadas | B23: -7964 | C23: 1302 | D23: 111 | E23: =IFERROR((D23-C23)/ABS(C23),"") -> -0.91474654
A24: Impostos a recuperar | B24: -94 | C24: -5 | D24: -470 | E24: =IFERROR((D24-C24)/ABS(C24),"") -> -93
A25: Créditos tributários | B25: 868 | C25: 0 | D25: 1822 | E25: =IFERROR((D25-C25)/ABS(C25),"")
A26: Outros ativos | B26: -342 | C26: -2 | D26: -190 | E26: =IFERROR((D26-C26)/ABS(C26),"") -> -94
A27: Depósitos judiciais | B27: -2437 | C27: -466 | D27: 3137 | E27: =IFERROR((D27-C27)/ABS(C27),"") -> 7.7317597
A28: Fornecedores | B28: 11902 | C28: 99431 | D28: -19845 | E28: =IFERROR((D28-C28)/ABS(C28),"") -> -1.1995856
A29: Obrigações sociais e trabalhistas | B29: 5857 | C29: 7169 | D29: 2745 | E29: =IFERROR((D29-C29)/ABS(C29),"") -> -0.61710141
A30: Impostos e contribuições a recolher | B30: -25565 | C30: 4996 | D30: -11877 | E30: =IFERROR((D30-C30)/ABS(C30),"") -> -3.3773018
A31: Imagem e comissões a pagar | B31: 100065 | C31: 130896 | D31: -123347 | E31: =IFERROR((D31-C31)/ABS(C31),"") -> -1.9423283
... A35: RCE | B35: -44233 | C35: -29200 | D35: -193537 | E35: =IFERROR((D35-C35)/ABS(C35),"") -> -5.6279795
A36: Provisão para riscos judiciais | B36: 30817 | C36: -29336 | D36: -44385 | E36: =IFERROR((D36-C36)/ABS(C36),"") -> -0.51298746 | F36: Reclassificação contábil — não é entrada de caixa real
A37: Passivo Concursal — RJ | B37: 0 | C37: 0 | D37: 457859 | E37: =IFERROR((D37-C37)/ABS(C37),"")
A38: Passivo contratual | B38: 103804 | C38: 4088 | D38: -18060 | E38: =IFERROR((D38-C38)/ABS(C38),"") -> -5.4178082
A39: Subtotal variações de capital de giro | B39: =SUM(B20:B38) -> 112832 | C39: =SUM(C20:C38) -> 172801 | D39: =SUM(D20:D38) -> -103703 | E39: =IFERROR((D39-C39)/ABS(C39),"") -> -1.6001296
A40: Caixa líquido das atividades operacionais (CFO) | B40: =B6+B18+B39 -> 127675 | C40: =C6+C18+C39 -> 205903 | D40: =D6+D18+D39 -> 92044 | E40: =IFERROR((D40-C40)/ABS(C40),"") -> -0.55297397
A42: ATIVIDADES DE INVESTIMENTO
A43: Aquisições de imobilizado e intangível (atletas) | B43: -171226 | C43: -189422 | D43: -162595 | E43: =IFERROR((D43-C43)/ABS(C43),"") -> 0.14162558
A44: Aplicação financeira vinculada | B44: -2068 | C44: 0 | D44: 0 | E44: =IFERROR((D44-C44)/ABS(C44),"")
A45: Caixa líquido das atividades de investimento (CFI) | B45: =B43+B44 -> -173294 | C45: =C43+C44 -> -189422 | D45: =D43+D44 -> -162595 | E45: =IFERROR((D45-C45)/ABS(C45),"") -> 0.14162558
...

Sheet Operacional Puro
A1: Vasco SAF — Reconciliação para Operacional Recorrente Puro
A2: EBITDA reportado vs. EBITDA recorrente puro (ex-deságios RJ, ex-vendas atletas, ex-apropriação histórica)
A4: Linha | B4: 2023 reapr. | C4: 2024 | D4: 2025 | E4: Δ 25 vs 24 | F4: Notas
A5: PARTIDA — DRE REPORTADA
A6: Resultado operacional antes do financeiro | B6: -70493 | C6: -56589 | D6: -126472 | E6: =IFERROR((D6-C6)/ABS(C6),"") -> -1.234922
A7: (+) Amortização direitos sobre atletas (custo) | B7: 58879 | C7: 91932 | D7: 124676 | E7: =IFERROR((D7-C7)/ABS(C7),"") -> 0.3561763
A8: (+) Depreciação e amortização (DGA) | B8: 0 | C8: 2987 | D8: 3443 | E8: =IFERROR((D8-C8)/ABS(C8),"") -> 0.15266153 | F8: Estimativa de outras amortizações dentro de custos operacionais
A9: (+) Outras amortizações (custo, baixa atletas) | B9: 9196 | C9: 4755 | D9: 4943 | E9: =IFERROR((D9-C9)/ABS(C9),"") -> 0.039537329
A10: EBITDA reportado | B10: =B6+B7+B8+B9 -> -2418 | C10: =C6+C7+C8+C9 -> 43085 | D10: =D6+D7+D8+D9 -> 6590 | E10: =IFERROR((D10-C10)/ABS(C10),"") -> -0.84704654
A12: AJUSTES PARA OPERACIONAL RECORRENTE PURO
A13: (-) Receita com transação de atletas | B13: -127181 | C13: -170258 | D13: -123866 | E13: =IFERROR((D13-C13)/ABS(C13),"") -> 0.27248059
A14: (+) Custo com transação de atletas | B14: 48981 | C14: 74826 | D14: 81257 | E14: =IFERROR((D14-C14)/ABS(C14),"") -> 0.085946062
A15: Subtotal: ganho líquido venda atletas (a remover) | B15: =B13+B14 -> -78200 | C15: =C13+C14 -> -95432 | D15: =D13+D14 -> -42609 | E15: =IFERROR((D15-C15)/ABS(C15),"") -> 0.55351454 | F15: Nota 29.ii do BP 2025: deságios PRJ alocados aqui
A16: (-) Deságios da RJ em "Outras Receitas Operacionais" | B16: 0 | C16: 0 | D16: -114285 | E16: =IFERROR((D16-C16)/ABS(C16),"") | F16: Receita histórica reconhecida — sem caixa em 2023
A17: (-) Apropriação luvas Globo 2016 (não-caixa) | B17: -55461 | C17: 0 | D17: 0 | E17: =IFERROR((D17-C17)/ABS(C17),"")
A19: EBITDA recorrente puro (operação sem windfall) | B19: =B10+B15+B16+B17 -> -136079 | C19: =C10+C15+C16+C17 -> -52347 | D19: =D10+D15+D16+D17 -> -150304 | E19: =IFERROR((D19-C19)/ABS(C19),"") -> -1.8713011
A20: Receita líquida operacional pura (recorrente caixa) | B20: ='Receita Detalhada'!B26 -> 170856.92 | C20: ='Receita Detalhada'!C26 -> 282340 | D20: ='Receita Detalhada'!D26 -> 415294 | E20: =IFERROR((D20-C20)/ABS(C20),"") -> 0.47090033
A21: Margem EBITDA recorrente puro / receita recorrente caixa | B21: =B19/B20 -> -0.79645001 | C21: =C19/C20 -> -0.18540412 | D21: =D19/D20 -> -0.36192192 | E21: =IFERROR((D21-C21)/ABS(C21),"") -> -0.95207048
A23: GAP A FECHAR (ESTRUTURAL)
A24: Gap operacional puro ao ano (= -EBITDA puro) | B24: =-B19 -> 136079 | C24: =-C19 -> 52347 | D24: =-D19 -> 150304 | E24: =IFERROR((D24-C24)/ABS(C24),"") -> 1.8713011 | F24: Quanto a operação recorrente "queima" por ano antes de juros, tributos e capex em atletas
A25: Cobertura por venda atletas (líq.) | B25: =-B15 -> 78200 | C25: =-C15 -> 95432 | D25: =-D15 -> 42609 | E25: =IFERROR((D25-C25)/ABS(C25),"") -> -0.55351454
A26: Gap residual (após venda atletas) | B26: =-B19-B25 -> 57879 | C26: =-C19-C25 -> -43085 | D26: =-D19-D25 -> 107695 | E26: =IFERROR((D26-C26)/ABS(C26),"") -> 3.4995938
A28: Notas:
A29: • EBITDA reportado de 2024 (R$ 38,7 M positivo) é a métrica destacada no Relatório da Administração — mas inclui R$ 95 M de ganho líquido com venda de atletas.
A30: • EBITDA reportado de 2025 (~R$ 3 M) inclui R$ 114 M de deságios contábeis da RJ + R$ 43 M de ganho líquido venda de atletas.
A31: • EBITDA recorrente puro mede a operação como negócio em estado de regime — sem ganhos pontuais de venda de atletas e sem efeitos contábeis da RJ.
A32: • O gap residual indica quanto de capital novo (aporte ou dívida nova) é necessário ao ano para a operação recorrente fechar — assumindo que venda de atletas se mantenha.
A33: • Em 2025 o gap residual cresceu — efeito (i) custos disparando, (ii) provisão para contingências subindo de R$ 9,6 M para R$ 69 M na DGA, (iii) ganho de venda de atletas caindo (Rayan veio só em 2026).

Sheet Indicadores
A1: Vasco SAF — Indicadores Chave
A2: Síntese para o post
A4: Indicador | B4: 2023 reapr. | C4: 2024 | D4: 2025 | E4: Δ 25 vs 24 | F4: Comentário
A5: LIQUIDEZ
A6: Caixa final (R$ mil) | B6: 79926 | C6: 28504 | D6: 60344 | E6: =IFERROR((D6-C6)/ABS(C6),"") -> 1.1170362
A7: Capital circulante líquido (AC - PC) | B7: -199013 | C7: -278515 | D7: -204464 | E7: =IFERROR((D7-C7)/ABS(C7),"") -> 0.26587796
A8: Liquidez corrente (AC/PC) | B8: 0.464 | C8: 0.408 | D8: 0.468 | E8: =IFERROR((D8-C8)/ABS(C8),"") -> 0.14705882
A9: Caixa final como % da receita líquida | B9: =B6/DRE!B5 -> 0.35987951 | C9: =C6/DRE!C5 -> 0.10095629 | D9: =D6/DRE!D5 -> 0.14580142 | E9: =IFERROR((D9-C9)/ABS(C9),"") -> 0.44420337
A11: ENDIVIDAMENTO
A12: PL (passivo a descoberto) | B12: -612910 | C12: -734270 | D12: -647490 | E12: =IFERROR((D12-C12)/ABS(C12),"") -> 0.11818541
A13: Dívida histórica assumida (registro contábil) | B13: -592624 | C13: -592624 | D13: -592624 | E13: =IFERROR((D13-C13)/ABS(C13),"") -> 0
A14: Capital a integralizar (777, em aberto) | B14: -383419 | C14: -383419 | D14: -383419 | E14: =IFERROR((D14-C14)/ABS(C14),"") -> 0
A15: Empréstimos e financiamentos totais | B15: 44656 | C15: 4330 | D15: 99379 | E15: =IFERROR((D15-C15)/ABS(C15),"") -> 21.95127 | F15: 2025: inclui DIP Crefisa de R$ 80 M
A17: OPERACIONAL
A18: Receita operacional líquida (R$ mil) | B18: 222091 | C18: 282340 | D18: 413878 | E18: =IFERROR((D18-C18)/ABS(C18),"") -> 0.4658851
A19: EBITDA reportado | B19: ='Operacional Puro'!B10 -> -2418 | C19: ='Operacional Puro'!C10 -> 43085 | D19: ='Operacional Puro'!D10 -> 6590 | E19: =IFERROR((D19-C19)/ABS(C19),"") -> -0.84704654
A20: EBITDA recorrente puro | B20: ='Operacional Puro'!B19 -> -136079 | C20: ='Operacional Puro'!C19 -> -52347 | D20: ='Operacional Puro'!D19 -> -150304 | E20: =IFERROR((D20-C20)/ABS(C20),"") -> -1.8713011
A21: Gap residual após venda atletas (R$ mil/ano) | B21: ='Operacional Puro'!B26 -> 57879 | C21: ='Operacional Puro'!C26 -> -43085 | D21: ='Operacional Puro'!D26 -> 107695 | E21: =IFERROR((D21-C21)/ABS(C21),"") -> 3.4995938
A23: INVESTIMENTO E FOLHA
A24: Capex em atletas + imobilizado (R$ mil) | B24: 171226 | C24: 189422 | D24: 162595 | E24: =IFERROR((D24-C24)/ABS(C24),"") -> -0.14162558
A25: Folha consolidada (custo + DGA) | B25: 145701 | C25: 178973 | D25: 232489 | E25: =IFERROR((D25-C25)/ABS(C25),"") -> 0.29901717
A26: Folha mensal média (R$ mil) | B26: =B25/12 -> 12141.75 | C26: =C25/12 -> 14914.417 | D26: =D25/12 -> 19374.083 | E26: =IFERROR((D26-C26)/ABS(C26),"") -> 0.29901717
A27: Folha como % da receita operacional líquida | B27: =B25/DRE!B5 -> 0.65604189 | C27: =C25/DRE!C5 -> 0.63389176 | D27: =D25/DRE!D5 -> 0.56173317 | E27: =IFERROR((D27-C27)/ABS(C27),"") -> -0.11383425
A29: OPINIÃO DO AUDITOR
A30: Auditor | B30: Grant Thornton | C30: BDO RCS | D30: BDO RCS
A31: Tipo de opinião | B31: Sem ressalvas (com ênfase) | C31: Abstenção de opinião | D31: Com ressalva
A32: Razão da limitação | B32: Continuidade operacional dependia de aportes 777 | C32: PRJ não aprovado; impairment não testado; doc. suporte | D32: AVP RJ não validado; LFF/FFU superavaliada R$ 104 M
A34: SÍNTESE PARA A TESE DO POST
A35: Pergunta-tese: "O Vasco SAF tem geração de caixa recorrente suficiente para sobreviver sozinho, ou precisa vender a SAF o quanto antes?" Resposta dos números nos 3 anos completos da SAF: • EBITDA recorrente puro foi negativo em todos os anos (entre R$ -57 M e R$ -154 M). • A operação só fechou caixa em 2023-2024 graças aos aportes da 777 e à entrada da LFF. • Em 2025, só fechou caixa com R$ 80 M de DIP do Banco Crefisa. • O lucro de R$ 81 M em 2025 é 100% decorrente da homologação da RJ — sem caixa associado. • A operação recorrente puro não fechou nem com 47% de crescimento de receita líquida em 2025. Conclusão: a primeira parte da tese é resolvida pelos balanços. A SAF não tem geração suficiente para sobreviver sozinha. A segunda parte ("o quanto antes") depende de quão rápido o capital novo precisa entrar — questão que está em aberto e é o conteúdo prospectivo do post.

Sheet Premissas Runway
A1: Vasco SAF — Premissas Modelo de Runway 2026
A2: Edite as células em azul para sensibilizar o modelo. R$ mil quando aplicável.
B4: Otimista | C4: Base | D4: Pessimista | E4: Lógica
A5: RECEITA OPERACIONAL
A6: Δ% receita recorrente líquida 2026 vs 2025 | B6: -0.075 | C6: -0.15 | D6: -0.25 | E6: Otim: leve / Base: moderada / Pess: forte (sem patrocínio master + bilheteria/premiação 2025 inflacionadas pela final no Maracanã)
A8: FOLHA AMPLIADA (salários + encargos + direito de imagem)
A9: Δ% folha ampliada 2026 vs 2025 | B9: -0.2 | C9: -0.12 | D9: -0.12 | E9: Otim: corte forte (saída Rayan, Coutinho, Vegetti sem reposição) / Base e Pess: moderada (saídas com reposições parciais)
A11: VENDA RAYAN — RECEBIMENTOS
A12: Valor bruto Rayan (R$ mil) | B12: 220000 | C12: 220000 | D12: 220000 | E12: Valor anunciado/estimado Bournemouth
A13: (-) Comissões agentes (% do bruto) | B13: 0.12 | C13: 0.12 | D13: 0.12 | E13: Padrão de mercado: ~10-15% para agentes
A14: (-) Solidariedade FIFA + clubes formadores + outras participações | B14: 0.18 | C14: 0.18 | D14: 0.18 | E14: Inclui solidariedade FIFA (5%), clubes formadores e participação de terceiros — total para chegar no líquido reportado de ~R$ 153M
A15: (-) TEF (5% receita caixa, regime especial) | B15: 0 | C15: 0 | D15: 0 | E15: Vendas de atletas FORA da base do TEF até 2027 (Nota 2.9 do BP 2023)
A16: % do bruto recebido em 2026 (lag de pagamento) | B16: 1 | C16: 1 | D16: 1 | E16: Recebimento à vista — condição da venda do Rayan ao Bournemouth
A18: CAPEX EM ATLETAS
A19: Capex em atletas 2026 (R$ mil) | B19: 80000 | C19: 80000 | D19: 130000 | E19: Conservador: foco em base + empréstimos / Moderado: reposição plena de Rayan, Coutinho, Vegetti
A20: % capex pago à vista no ano (lag fornecedores) | B20: 0.4 | C20: 0.4 | D20: 0.4 | E20: Vasco historicamente paga 30-50% à vista, resto a prazo
A22: OUTROS CUSTOS E DESPESAS OPERACIONAIS
A23: Outros custos operacionais 2026 (R$ mil) | B23: 95000 | C23: 100000 | D23: 105000 | E23: Jogos, materiais, manutenção, serviços profissionais (ex-folha, ex-imagem)
A24: DGA (ex-salários, ex-provisões): serviços, manutenção, etc. | B24: 35000 | C24: 40000 | D24: 45000 | E24: Em 2025 a DGA ex-salários foi ~R$ 130M, dos quais R$ 69M de provisões — exclui-se provisões pra projetar caixa
A26: PAGAMENTOS DA RECUPERAÇÃO JUDICIAL
A27: Trabalhistas Classe I (10 anos IPCA+2%, trim.) | B27: 8000 | C27: 9000 | D27: 10000 | E27: Sem deságio. Estimativa baseada na proporção do passivo trab. dentro do total RJ
A28: Trabalhistas não-colab. (92% deságio em 12m) | B28: 4000 | C28: 5000 | D28: 6000 | E28: Concentrado em 2026 (12 meses) limitado a 150 SM por credor
A29: Federações (3 anos integral, IPCA) | B29: 3000 | C29: 4000 | D29: 5000 | E29: Sem deságio, pago em 3 anos (~R$ 12-15M total / 3)
A30: Direito de imagem (9 anos, 30% deságio, IPCA) | B30: 4000 | C30: 5000 | D30: 6000 | E30: Direitos de imagem retidos no PRJ pagos em 9 anos com 30% de desconto
A31: Outros (CNRD, fornecedores parceiros, clubes parceiros) | B31: 6000 | C31: 8000 | D31: 12000 | E31: Quirografários Classe III (90% deságio, 36m carência) — R$ 0 em 2026 ainda
A32: Subtotal pagamentos RJ 2026 | B32: =SUM(B27:B31) -> 25000 | C32: =SUM(C27:C31) -> 31000 | D32: =SUM(D27:D31) -> 39000
A34: OUTRAS SAÍDAS DE CAIXA RECORRENTES
A35: Parcelamentos não-RJ (PGFN/RFB/CEDAE) — fora do PRJ | B35: 38000 | C35: 38000 | D35: 38000 | E35: Cronograma da Nota 16 do BP 2023: ~R$ 38M/ano até 2028
A36: Imagem e transações de atletas a pagar (parcelas anteriores) | B36: 80000 | C36: 95000 | D36: 110000 | E36: Saldo no BP 2025 = R$ 113M circulante. Otim: pagamento moderado / Pess: pagamento integral + juros
A37: Serviço da DIP Crefisa (juros + parte do principal) | B37: 25000 | C37: 30000 | D37: 35000 | E37: R$ 80M principal + spread DIP típico ~CDI+8-12% a.a. — pagamento parcelado em 24-36 meses
A38: Tributos da operação (TEF 5% s/ receita caixa) | B38: 18500 | C38: 17000 | D38: 15000 | E38: TEF 5% sobre receita recorrente bruta proporcional ao cenário
A40: Convenções:
A41: • Células em AZUL/AMARELO são editáveis. Pretas são fórmulas.
A42: • Cenário Otimista pressupõe gestão agressiva de custos + janela favorável.
A43: • Cenário Pessimista pressupõe a soma das pressões: receita cai forte + folha não consegue cortar tanto + capex alto.
A44: • Cenário Base é o "esperado" dadas as informações disponíveis em mai/2026.
A47: ═══ PREMISSAS PARA 2027 ═══
B48: Otimista | C48: Base | D48: Pessimista | E48: Lógica
A49: Δ% receita recorrente líquida 2027 vs 2026 | B49: 0 | C49: -0.05 | D49: -0.1 | E49: Otim: estabilidade / Base: queda residual / Pess: continua queda
A50: Δ% folha ampliada 2027 vs 2026 | B50: 0 | C50: 0.05 | D50: 0.1 | E50: Otim: estabilidade pós-corte / Base/Pess: cresce com reposições
...

Sheet Modelo Runway
A1: Vasco SAF — Modelo de Runway 2026
A2: Demonstração simplificada de fluxo de caixa por cenário. Valores em R$ mil.
B4: Otimista | C4: Base | D4: Pessimista | E4: Memória de cálculo | F4: Otim 2027 | G4: Base 2027 | H4: Pess 2027
A5: Caixa inicial (2026: caixa final 2025; 2027: assume = 0 com gap 2026 coberto por financiamento) | B5: 60344 | C5: 60344 | D5: 60344 | F5: 0 | G5: 0 | H5: 0
A7: ENTRADAS DE CAIXA
A8: Receita recorrente líquida 2026 (entrada caixa) | B8: =413878*(1+'Premissas Runway'!B6)*0.95 -> 363695.29 | C8: =413878*(1+'Premissas Runway'!C6)*0.95 -> 334206.48 | D8: =413878*(1+'Premissas Runway'!D6)*0.95 -> 294888.08 | E8: R$ 414M (rec. líq. 2025) × (1+Δ%) × 95% (lag de 30 dias) | F8: =B8*(1+'Premissas Runway'!B49) -> 363695.29 | G8: =C8*(1+'Premissas Runway'!C49) -> 317496.16 | H8: =D8*(1+'Premissas Runway'!D49) -> 265399.27
A9: Recebimento Rayan (parcelas remanescentes em 2027) | B9: ='Premissas Runway'!B12*(1-'Premissas Runway'!B13-'Premissas Runway'!B14)*'Premissas Runway'!B16 -> 154000 | C9: ='Premissas Runway'!C12*(1-'Premissas Runway'!C13-'Premissas Runway'!C14)*'Premissas Runway'!C16 -> 154000 | D9: ='Premissas Runway'!D12*(1-'Premissas Runway'!D13-'Premissas Runway'!D14)*'Premissas Runway'!D16 -> 154000 | E9: Bruto × (1 - comissão - solidariedade) × % recebido em 2026 | F9: ='Premissas Runway'!B12*(1-'Premissas Runway'!B13-'Premissas Runway'!B14)*(1-'Premissas Runway'!B16) -> 0 | G9: ='Premissas Runway'!C12*(1-'Premissas Runway'!C13-'Premissas Runway'!C14)*(1-'Premissas Runway'!C16) -> 0 | H9: ='Premissas Runway'!D12*(1-'Premissas Runway'!D13-'Premissas Runway'!D14)*(1-'Premissas Runway'!D16) -> 0
A10: Andrés Gómez + outras vendas atletas 2027 | B10: 25000 | C10: 25000 | D10: 25000 | E10: Parcelas pendentes de João Victor, Luiz Gustavo, Erick Marcus etc. | F10: ='Premissas Runway'!B51+'Premissas Runway'!B52 -> 125000 | G10: ='Premissas Runway'!C51+'Premissas Runway'!C52 -> 110000 | H10: ='Premissas Runway'!D51+'Premissas Runway'!D52 -> 95000
A11: Total entradas de caixa 2026 | B11: =SUM(B8:B10) -> 542695.29 | C11: =SUM(C8:C10) -> 513206.48 | D11: =SUM(D8:D10) -> 473888.08 | F11: =SUM(F8:F10) -> 488695.29 | G11: =SUM(G8:G10) -> 427496.16 | H11: =SUM(H8:H10) -> 360399.27
A13: SAÍDAS DE CAIXA
A14: Folha ampliada 2026 (salários + encargos + imagem) | B14: =-315000*(1+'Premissas Runway'!B9) -> -252000 | C14: =-315000*(1+'Premissas Runway'!C9) -> -277200 | D14: =-315000*(1+'Premissas Runway'!D9) -> -277200 | E14: R$ 315M (folha ampliada 2025) × (1+Δ%) | F14: =B14*(1+'Premissas Runway'!B50) -> -252000 | G14: =C14*(1+'Premissas Runway'!C50) -> -291060 | H14: =D14*(1+'Premissas Runway'!D50) -> -304920
A15: Outros custos operacionais (jogos, materiais, manut., serviços) | B15: =-'Premissas Runway'!B23 -> -95000 | C15: =-'Premissas Runway'!C23 -> -100000 | D15: =-'Premissas Runway'!D23 -> -105000 | E15: Premissa direta da aba Premissas | F15: =-'Premissas Runway'!B54 -> -100000 | G15: =-'Premissas Runway'!C54 -> -105000 | H15: =-'Premissas Runway'!D54 -> -110000
A16: DGA caixa (ex-salários, ex-provisões) | B16: =-'Premissas Runway'!B24 -> -35000 | C16: =-'Premissas Runway'!C24 -> -40000 | D16: =-'Premissas Runway'!D24 -> -45000 | E16: Premissa direta da aba Premissas | F16: =-'Premissas Runway'!B55 -> -38000 | G16: =-'Premissas Runway'!C55 -> -42000 | H16: =-'Premissas Runway'!D55 -> -48000
A17: Capex em atletas pago à vista em 2026 | B17: =-'Premissas Runway'!B19*'Premissas Runway'!B20 -> -32000 | C17: =-'Premissas Runway'!C19*'Premissas Runway'!C20 -> -32000 | D17: =-'Premissas Runway'!D19*'Premissas Runway'!D20 -> -52000 | E17: Capex × % à vista. Restante vai para "imagem e transações de atletas a pagar" em 2027+ | F17: =-'Premissas Runway'!B53*0.4 -> -32000 | G17: =-'Premissas Runway'!C53*0.4 -> -32000 | H17: =-'Premissas Runway'!D53*0.4 -> -52000
A18: Pagamentos da RJ (Classe I, Federações, Imagem, etc.) | B18: =-'Premissas Runway'!B32 -> -25000 | C18: =-'Premissas Runway'!C32 -> -31000 | D18: =-'Premissas Runway'!D32 -> -39000 | E18: Subtotal RJ da aba Premissas (Classes I, Fed, Imagem, Outros) | F18: =-'Premissas Runway'!B56 -> -28000 | G18: =-'Premissas Runway'!C56 -> -33000 | H18: =-'Premissas Runway'!D56 -> -40000
A19: Parcelamentos não-RJ (PGFN/RFB/CEDAE) | B19: =-'Premissas Runway'!B35 -> -38000 | C19: =-'Premissas Runway'!C35 -> -38000 | D19: =-'Premissas Runway'!D35 -> -38000 | E19: Estável (~R$ 38M/ano por 5 anos) | F19: =-'Premissas Runway'!B57 -> -38000 | G19: =-'Premissas Runway'!C57 -> -38000 | H19: =-'Premissas Runway'!D57 -> -38000
A20: Imagem e transações de atletas a pagar (parcelas) | B20: =-'Premissas Runway'!B36 -> -80000 | C20: =-'Premissas Runway'!C36 -> -95000 | D20: =-'Premissas Runway'!D36 -> -110000 | E20: Saldo do BP 2025 (R$ 113M circ + R$ 5M NC) saindo no ano | F20: =-'Premissas Runway'!B58 -> -50000 | G20: =-'Premissas Runway'!C58 -> -60000 | H20: =-'Premissas Runway'!D58 -> -80000
A21: Serviço da DIP Crefisa (juros + amortização) | B21: =-'Premissas Runway'!B37 -> -25000 | C21: =-'Premissas Runway'!C37 -> -30000 | D21: =-'Premissas Runway'!D37 -> -35000 | E21: R$ 80M principal sendo amortizado em 24-36m + juros | F21: =-'Premissas Runway'!B59 -> -55000 | G21: =-'Premissas Runway'!C59 -> -60000 | H21: =-'Premissas Runway'!D59 -> -65000
A22: TEF (5% s/ receita recorrente caixa) | B22: =-'Premissas Runway'!B38 -> -18500 | C22: =-'Premissas Runway'!C38 -> -17000 | D22: =-'Premissas Runway'!D38 -> -15000 | E22: Vendas de atletas isentas até 2027 (Lei 14.193/21) | F22: =-'Premissas Runway'!B60 -> -18000 | G22: =-'Premissas Runway'!C60 -> -16500 | H22: =-'Premissas Runway'!D60 -> -14000
A23: Total saídas de caixa 2026 | B23: =SUM(B14:B22) -> -600500 | C23: =SUM(C14:C22) -> -660200 | D23: =SUM(D14:D22) -> -716200 | F23: =SUM(F14:F22) -> -611000 | G23: =SUM(G14:G22) -> -677560 | H23: =SUM(H14:H22) -> -751920
A25: RESULTADO DO ANO
A26: Variação líquida de caixa 2026 | B26: =B11+B23 -> -57804.708 | C26: =C11+C23 -> -146993.52 | D26: =D11+D23 -> -242311.92 | F26: =F11+F23 -> -122304.71 | G26: =G11+G23 -> -250063.84 | H26: =H11+H23 -> -391520.73
A27: Caixa final 2026 (antes de novo financiamento) | B27: =B5+B26 -> 2539.2925 | C27: =C5+C26 -> -86649.515 | D27: =D5+D26 -> -181967.92 | F27: =F5+F26 -> -122304.71 | G27: =G5+G26 -> -250063.84 | H27: =H5+H26 -> -391520.73
A29: MÉTRICAS DE PRESSÃO
A30: Burn mensal médio (saídas - entradas) / 12 | B30: =IF(B26<0,-B26/12,0) -> 4817.059 | C30: =IF(C26<0,-C26/12,0) -> 12249.46 | D30: =IF(D26<0,-D26/12,0) -> 20192.66 | E30: Quanto a SAF queima por mês quando saídas > entradas | F30: =IF(F26<0,-F26/12,0) -> 10192.059 | G30: =IF(G26<0,-G26/12,0) -> 20838.653 | H30: =IF(H26<0,-H26/12,0) -> 32626.728
A31: Runway estimado (meses até zerar caixa) | B31: =IF(B30>0,B5/B30,"sustentável") -> 12.527146 | C31: =IF(C30>0,C5/C30,"sustentável") -> 4.9262581 | D31: =IF(D30>0,D5/D30,"sustentável") -> 2.9884126 | E31: Caixa inicial / burn mensal. "sustentável" significa CFO positivo | F31: =IF(F30>0,F5/F30,"sustentável") -> 0 | G31: =IF(G30>0,G5/G30,"sustentável") -> 0 | H31: =IF(H30>0,H5/H30,"sustentável") -> 0
A32: Necessidade adicional de financiamento em 2026 | B32: =IF(B27<0,-B27,0) -> 0 | C32: =IF(C27<0,-C27,0) -> 86649.515 | D32: =IF(D27<0,-D27,0) -> 181967.92 | E32: Quanto de novo aporte/dívida/venda extra precisa entrar no ano | F32: =IF(F27<0,-F27,0) -> 122304.71 | G32: =IF(G27<0,-G27,0) -> 250063.84 | H32: =IF(H27<0,-H27,0) -> 391520.73
A34: LEITURA PARA O POST
A35: Mesmo no cenário Otimista (Vasco corta folha agressivamente, contração de receita é leve, Rayan recebe 65% do bruto em 2026, capex baixo), a operação aproxima-se do equilíbrio mas depende do calibre exato das premissas. Nos cenários Base e Pessimista, a SAF entra em novo aperto de caixa em 2026 mesmo com a venda do Rayan. A leitura central é que a venda do Rayan resolve 2026 nos cenários intermediários, mas não cria capacidade estrutural de geração de caixa: ela apenas compensa a queda de receita recorrente e os pagamentos da RJ. Em 2027 (sem outro Rayan), o gap estrutural reaparece. Pro post: a contraposição é "vender atletas vez por ano para tampar buraco" vs "vender a SAF (UPI ou via A-CAP) para desfazer o buraco de uma vez".

Sheet Resumo Cenários
A1: Vasco SAF — Resumo dos 3 Cenários
A2: Visão consolidada: o que cada cenário diz sobre 2026.
B4: Otimista | C4: Base | D4: Pessimista
A5: PREMISSAS-CHAVE
A6: Δ% receita recorrente líquida | B6: ='Premissas Runway'!B6 -> -0.075 | C6: ='Premissas Runway'!C6 -> -0.15 | D6: ='Premissas Runway'!D6 -> -0.25
A7: Δ% folha ampliada | B7: ='Premissas Runway'!B9 -> -0.2 | C7: ='Premissas Runway'!C9 -> -0.12 | D7: ='Premissas Runway'!D9 -> -0.12
A8: Capex em atletas (R$ mil) | B8: ='Premissas Runway'!B19 -> 80000 | C8: ='Premissas Runway'!C19 -> 80000 | D8: ='Premissas Runway'!D19 -> 130000
A9: % bruto Rayan recebido em 2026 | B9: ='Premissas Runway'!B16 -> 1 | C9: ='Premissas Runway'!C16 -> 1 | D9: ='Premissas Runway'!D16 -> 1
A11: RESULTADOS CALCULADOS
A12: Total entradas de caixa 2026 (R$ mil) | B12: ='Modelo Runway'!B11 -> 542695.29 | C12: ='Modelo Runway'!C11 -> 513206.48 | D12: ='Modelo Runway'!D11 -> 473888.08
A13: Total saídas de caixa 2026 (R$ mil) | B13: ='Modelo Runway'!B23 -> -600500 | C13: ='Modelo Runway'!C23 -> -660200 | D13: ='Modelo Runway'!D23 -> -716200
A14: Variação de caixa no ano (R$ mil) | B14: ='Modelo Runway'!B26 -> -57804.708 | C14: ='Modelo Runway'!C26 -> -146993.52 | D14: ='Modelo Runway'!D26 -> -242311.92
A15: Caixa final 2026 antes de novo financiamento (R$ mil) | B15: ='Modelo Runway'!B27 -> 2539.2925 | C15: ='Modelo Runway'!C27 -> -86649.515 | D15: ='Modelo Runway'!D27 -> -181967.92
A16: Necessidade adicional de financiamento (R$ mil) | B16: ='Modelo Runway'!B32 -> 0 | C16: ='Modelo Runway'!C32 -> 86649.515 | D16: ='Modelo Runway'!D32 -> 181967.92

Sheet Caminho A — Trajetória
A1: Vasco SAF — Caminho A: Trajetória até Competitividade Financeira
A2: Atendimento das 4 condições mínimas em cada cenário (2025 atual / 2026 / 2027). R$ mil quando aplicável.
B4: 2025 | C4: Otim 2026 | D4: Base 2026 | E4: Pess 2026 | F4: Otim 2027 | G4: Base 2027 | H4: Pess 2027 | I4: Meta
A5: RECEITA OPERACIONAL LÍQUIDA (R$ mil)
A6: Receita líquida operacional | B6: 413878 | C6: ='Modelo Runway'!B8 -> 363695.29 | D6: ='Modelo Runway'!C8 -> 334206.48 | E6: ='Modelo Runway'!D8 -> 294888.08 | F6: ='Modelo Runway'!F8 -> 363695.29 | G6: ='Modelo Runway'!G8 -> 317496.16 | H6: ='Modelo Runway'!H8 -> 265399.27
A8: CONDIÇÃO 1 — Folha ampliada ≤ 65% da receita
A9: Folha ampliada (R$ mil) | B9: 315000 | C9: =-'Modelo Runway'!B14 -> 252000 | D9: =-'Modelo Runway'!C14 -> 277200 | E9: =-'Modelo Runway'!D14 -> 277200 | F9: =-'Modelo Runway'!F14 -> 252000 | G9: =-'Modelo Runway'!G14 -> 291060 | H9: =-'Modelo Runway'!H14 -> 304920
A10: Folha / Receita líquida | B10: =B9/B6 -> 0.76109385 | C10: =C9/C6 -> 0.69288771 | D10: =D9/D6 -> 0.82942735 | E10: =E9/E6 -> 0.94001767 | F10: =F9/F6 -> 0.69288771 | G10: =G9/G6 -> 0.91673549 | H10: =H9/H6 -> 1.1489105 | I10: ≤ 65%
A11: Atende? | B11: =IF(B10<=0.65,"✓","✗") -> ✗ | C11: =IF(C10<=0.65,"✓","✗") -> ✗ | D11: =IF(D10<=0.65,"✓","✗") -> ✗ | E11: =IF(E10<=0.65,"✓","✗") -> ✗ | F11: =IF(F10<=0.65,"✓","✗") -> ✗ | G11: =IF(G10<=0.65,"✓","✗") -> ✗ | H11: =IF(H10<=0.65,"✓","✗") -> ✗
A13: CONDIÇÃO 2 — EBITDA recorrente puro positivo (≥ +5%)
A14: EBITDA recorrente puro (R$ mil) | B14: ='Operacional Puro'!D19 -> -150304 | C14: ='Modelo Runway'!B8+'Modelo Runway'!B14+'Modelo Runway'!B15+'Modelo Runway'!B16 -> -18304.708 | D14: ='Modelo Runway'!C8+'Modelo Runway'!C14+'Modelo Runway'!C15+'Modelo Runway'!C16 -> -82993.515 | E14: ='Modelo Runway'!D8+'Modelo Runway'!D14+'Modelo Runway'!D15+'Modelo Runway'!D16 -> -132311.92 | F14: ='Modelo Runway'!F8+'Modelo Runway'!F14+'Modelo Runway'!F15+'Modelo Runway'!F16 -> -26304.708 | G14: ='Modelo Runway'!G8+'Modelo Runway'!G14+'Modelo Runway'!G15+'Modelo Runway'!G16 -> -120563.84 | H14: ='Modelo Runway'!H8+'Modelo Runway'!H14+'Modelo Runway'!H15+'Modelo Runway'!H16 -> -197520.73
A15: Margem EBITDA recorrente puro | B15: =B14/B6 -> -0.36316016 | C15: =C14/C6 -> -0.050329789 | D15: =D14/D6 -> -0.24833006 | E15: =E14/E6 -> -0.44868523 | F15: =F14/F6 -> -0.072326225 | G15: =G14/G6 -> -0.37973322 | H15: =H14/H6 -> -0.74423993 | I15: ≥ +5%
A16: Atende? | B16: =IF(B15>=0.05,"✓","✗") -> ✗ | C16: =IF(C15>=0.05,"✓","✗") -> ✗ | D16: =IF(D15>=0.05,"✓","✗") -> ✗ | E16: =IF(E15>=0.05,"✓","✗") -> ✗ | F16: =IF(F15>=0.05,"✓","✗") -> ✗ | G16: =IF(G15>=0.05,"✓","✗") -> ✗ | H16: =IF(H15>=0.05,"✓","✗") -> ✗
C17: ='Premissas Runway'!B19 -> 80000 | D17: ='Premissas Runway'!C19 -> 80000 | E17: ='Premissas Runway'!D19 -> 130000
A18: CONDIÇÃO 3 — Capex em atletas ≤ venda de atletas (autofinanciamento)
A19: Capex em atletas total (R$ mil) | B19: 162595 | C19: ='Premissas Runway'!B19 -> 80000 | D19: ='Premissas Runway'!C19 -> 80000 | E19: ='Premissas Runway'!D19 -> 130000 | F19: ='Premissas Runway'!B53 -> 80000 | G19: ='Premissas Runway'!C53 -> 80000 | H19: ='Premissas Runway'!D53 -> 130000
A20: Receita venda atletas (R$ mil) | B20: 96755 | C20: ='Modelo Runway'!B9+'Modelo Runway'!B10 -> 179000 | D20: ='Modelo Runway'!C9+'Modelo Runway'!C10 -> 179000 | E20: ='Modelo Runway'!D9+'Modelo Runway'!D10 -> 179000 | F20: ='Modelo Runway'!F9+'Modelo Runway'!F10 -> 125000 | G20: ='Modelo Runway'!G9+'Modelo Runway'!G10 -> 110000 | H20: ='Modelo Runway'!H9+'Modelo Runway'!H10 -> 95000
A21: Capex / Venda (múltiplo) | B21: =B19/B20 -> 1.6804816 | C21: =C19/C20 -> 0.44692737 | D21: =D19/D20 -> 0.44692737 | E21: =E19/E20 -> 0.72625698 | F21: =F19/F20 -> 0.64 | G21: =G19/G20 -> 0.72727273 | H21: =H19/H20 -> 1.3684211 | I21: ≤ 1,00x
A22: Atende? | B22: =IF(B21<=1,"✓","✗") -> ✗ | C22: =IF(C21<=1,"✓","✗") -> ✓ | D22: =IF(D21<=1,"✓","✗") -> ✓ | E22: =IF(E21<=1,"✓","✗") -> ✓ | F22: =IF(F21<=1,"✓","✗") -> ✓ | G22: =IF(G21<=1,"✓","✗") -> ✓ | H22: =IF(H21<=1,"✓","✗") -> ✗
A24: CONDIÇÃO 4 — Caixa ≥ 1 mês de saídas operacionais
A25: Caixa final do ano (R$ mil) | B25: 60344 | C25: ='Modelo Runway'!B27 -> 2539.2925 | D25: ='Modelo Runway'!C27 -> -86649.515 | E25: ='Modelo Runway'!D27 -> -181967.92 | F25: ='Modelo Runway'!F27 -> -122304.71 | G25: ='Modelo Runway'!G27 -> -250063.84 | H25: ='Modelo Runway'!H27 -> -391520.73
A26: Saídas mensais médias (R$ mil/mês) | B26: 55000 | C26: =-'Modelo Runway'!B23/12 -> 50041.667 | D26: =-'Modelo Runway'!C23/12 -> 55016.667 | E26: =-'Modelo Runway'!D23/12 -> 59683.333 | F26: =-'Modelo Runway'!F23/12 -> 50916.667 | G26: =-'Modelo Runway'!G23/12 -> 56463.333 | H26: =-'Modelo Runway'!H23/12 -> 62660
A27: Caixa em meses de saídas | B27: =B25/B26 -> 1.0971636 | C27: =C25/C26 -> 0.050743564 | D27: =D25/D26 -> -1.5749685 | E27: =E25/E26 -> -3.0488901 | F27: =F25/F26 -> -2.4020564 | G27: =G25/G26 -> -4.4287828 | H27: =H25/H26 -> -6.248336 | I27: ≥ 1 mês
A28: Atende? | B28: =IF(B27>=1,"✓","✗") -> ✓ | C28: =IF(C27>=1,"✓","✗") -> ✗ | D28: =IF(D27>=1,"✓","✗") -> ✗ | E28: =IF(E27>=1,"✓","✗") -> ✗ | F28: =IF(F27>=1,"✓","✗") -> ✗ | G28: =IF(G27>=1,"✓","✗") -> ✗ | H28: =IF(H27>=1,"✓","✗") -> ✗
A30: SÍNTESE — Quantas condições atende?
A31: Total condições atendidas (de 4) | B31: =COUNTIF(B11,"✓")+COUNTIF(B16,"✓")+COUNTIF(B22,"✓")+COUNTIF(B28,"✓") -> 1 | C31: =COUNTIF(C11,"✓")+COUNTIF(C16,"✓")+COUNTIF(C22,"✓")+COUNTIF(C28,"✓") -> 1 | D31: =COUNTIF(D11,"✓")+COUNTIF(D16,"✓")+COUNTIF(D22,"✓")+COUNTIF(D28,"✓") -> 1 | E31: =COUNTIF(E11,"✓")+COUNTIF(E16,"✓")+COUNTIF(E22,"✓")+COUNTIF(E28,"✓") -> 1 | F31: =COUNTIF(F11,"✓")+COUNTIF(F16,"✓")+COUNTIF(F22,"✓")+COUNTIF(F28,"✓") -> 1 | G31: =COUNTIF(G11,"✓")+COUNTIF(G16,"✓")+COUNTIF(G22,"✓")+COUNTIF(G28,"✓") -> 1 | H31: =COUNTIF(H11,"✓")+COUNTIF(H16,"✓")+COUNTIF(H22,"✓")+COUNTIF(H28,"✓") -> 0
A33: Notas:
A34: • "Folha ampliada" inclui salários, encargos, direitos de imagem (custos operacionais + DGA), excluindo amortização de atletas.
A35: • "Capex em atletas" é o valor total de aquisições do ano (não apenas a parte paga à vista).
A36: • "Saídas mensais médias" = total saídas operacionais ÷ 12. Inclui pagamentos da RJ, parcelamentos, DIP, etc.
A37: • Capex/Venda em 2025 = 1,68x (162M comprou / 96M vendeu) — não atende a meta de autofinanciamento.
A38: • EBITDA recorrente puro = receita líquida − folha − outros custos − DGA (sem amortização nem provisões).
A39: • Caixa final 2026 e 2027 considera "antes de novo financiamento" — onde negativo, há gap.
A40: • Em 2027, o caixa inicial é assumido como 0 (premissa: gap 2026 coberto exatamente por financiamento).

Sheet Conformidade SSF
A1: Vasco SAF — Conformidade com SSF (Sistema de Sustentabilidade Financeira da CBF)
A2: Limites regulatórios em vigor a partir de 2026 para clubes Série A. R$ mil quando aplicável.
B4: 2025 | C4: Otim 2026 | D4: Base 2026 | E4: Pess 2026 | F4: Otim 2027 | G4: Base 2027 | H4: Pess 2027 | I4: Limite SSF
A5: PILAR 2 SSF — Custos com elenco / (Receita + Vendas + Aportes)
A6: Custos com elenco (= folha ampliada + amortização atletas) | B6: 440000 | C6: =-'Modelo Runway'!B14+125000 -> 377000 | D6: =-'Modelo Runway'!C14+125000 -> 402200 | E6: =-'Modelo Runway'!D14+125000 -> 402200 | F6: =-'Modelo Runway'!F14+115000 -> 367000 | G6: =-'Modelo Runway'!G14+115000 -> 406060 | H6: =-'Modelo Runway'!H14+115000 -> 419920
A7: Receita relevante (líquida + venda atletas + aportes) | B7: 510633 | C7: ='Modelo Runway'!B8+'Modelo Runway'!B9+'Modelo Runway'!B10 -> 542695.29 | D7: ='Modelo Runway'!C8+'Modelo Runway'!C9+'Modelo Runway'!C10 -> 513206.48 | E7: ='Modelo Runway'!D8+'Modelo Runway'!D9+'Modelo Runway'!D10 -> 473888.08 | F7: ='Modelo Runway'!F8+'Modelo Runway'!F9+'Modelo Runway'!F10 -> 488695.29 | G7: ='Modelo Runway'!G8+'Modelo Runway'!G9+'Modelo Runway'!G10 -> 427496.16 | H7: ='Modelo Runway'!H8+'Modelo Runway'!H9+'Modelo Runway'!H10 -> 360399.27
A8: Custos elenco / Receita relevante | B8: =B6/B7 -> 0.86167561 | C8: =C6/C7 -> 0.6946808 | D8: =D6/D7 -> 0.78370015 | E8: =E6/E7 -> 0.84872361 | F8: =F6/F7 -> 0.7509792 | G8: =G6/G7 -> 0.94985648 | H8: =H6/H7 -> 1.1651522 | I8: ≤ 80% em 2028 / ≤ 70% em 2029
A9: Atende limite 2028 (≤ 80%)? | B9: =IF(B8<=0.8,"✓","✗") -> ✗ | C9: =IF(C8<=0.8,"✓","✗") -> ✓ | D9: =IF(D8<=0.8,"✓","✗") -> ✓ | E9: =IF(E8<=0.8,"✓","✗") -> ✗ | F9: =IF(F8<=0.8,"✓","✗") -> ✓ | G9: =IF(G8<=0.8,"✓","✗") -> ✗ | H9: =IF(H8<=0.8,"✓","✗") -> ✗
A10: Atende limite 2029 (≤ 70%)? | B10: =IF(B8<=0.7,"✓","✗") -> ✗ | C10: =IF(C8<=0.7,"✓","✗") -> ✓ | D10: =IF(D8<=0.7,"✓","✗") -> ✗ | E10: =IF(E8<=0.7,"✓","✗") -> ✗ | F10: =IF(F8<=0.7,"✓","✗") -> ✗ | G10: =IF(G8<=0.7,"✓","✗") -> ✗ | H10: =IF(H8<=0.7,"✓","✗") -> ✗
A12: PILAR 1 SSF — Equilíbrio operacional (déficit ≤ R$ 30M ou 2,5% receita)
A13: Resultado operacional (R$ mil) | B13: -126472 | C13: =C7-C6-'Premissas Runway'!B23-'Premissas Runway'!B24 -> 35695.292 | D13: =D7-D6-'Premissas Runway'!C23-'Premissas Runway'!C24 -> -28993.515 | E13: =E7-E6-'Premissas Runway'!D23-'Premissas Runway'!D24 -> -78311.925 | F13: =F7-F6-'Premissas Runway'!B54-'Premissas Runway'!B55 -> -16304.708 | G13: =G7-G6-'Premissas Runway'!C54-'Premissas Runway'!C55 -> -125563.84 | H13: =H7-H6-'Premissas Runway'!D54-'Premissas Runway'!D55 -> -217520.73
A14: Limite máximo de déficit (R$ 30M ou 2,5% receita) | B14: =-MAX(30000,B7*0.025) -> -30000 | C14: =-MAX(30000,C7*0.025) -> -30000 | D14: =-MAX(30000,D7*0.025) -> -30000 | E14: =-MAX(30000,E7*0.025) -> -30000 | F14: =-MAX(30000,F7*0.025) -> -30000 | G14: =-MAX(30000,G7*0.025) -> -30000 | H14: =-MAX(30000,H7*0.025) -> -30000 | I14: Maior valor entre R$ 30M e 2,5% da receita
A15: Atende? | B15: =IF(B13>=B14,"✓","✗") -> ✗ | C15: =IF(C13>=C14,"✓","✗") -> ✓ | D15: =IF(D13>=D14,"✓","✗") -> ✓ | E15: =IF(E13>=E14,"✓","✗") -> ✗ | F15: =IF(F13>=F14,"✓","✗") -> ✓ | G15: =IF(G13>=G14,"✓","✗") -> ✗ | H15: =IF(H13>=H14,"✓","✗") -> ✗ | I15: Aproximação: receita relevante − elenco − outros op − DGA
A17: REGRA ESPECIAL RJ — Janela neutra (capex ≤ venda atletas)
A18: Capex / Venda atletas (mesma da Condição 3 do Caminho A) | B18: ='Caminho A — Trajetória'!B21 -> 1.6804816 | C18: ='Caminho A — Trajetória'!C21 -> 0.44692737 | D18: ='Caminho A — Trajetória'!D21 -> 0.44692737 | E18: ='Caminho A — Trajetória'!E21 -> 0.72625698 | F18: ='Caminho A — Trajetória'!F21 -> 0.64 | G18: ='Caminho A — Trajetória'!G21 -> 0.72727273 | H18: ='Caminho A — Trajetória'!H21 -> 1.3684211 | I18: ≤ 1,00x (regra para clubes em RJ)
A19: Atende? | B19: =IF(B18<=1,"✓","✗") -> ✗ | C19: =IF(C18<=1,"✓","✗") -> ✓ | D19: =IF(D18<=1,"✓","✗") -> ✓ | E19: =IF(E18<=1,"✓","✗") -> ✓ | F19: =IF(F18<=1,"✓","✗") -> ✓ | G19: =IF(G18<=1,"✓","✗") -> ✓ | H19: =IF(H18<=1,"✓","✗") -> ✗
A21: REGRA ESPECIAL RJ — Folha congelada (média últimos 6m)
A22: Folha mensal média do ano (R$ mil/mês) | B22: 26250 | C22: ='Caminho A — Trajetória'!C9/12 -> 21000 | D22: ='Caminho A — Trajetória'!D9/12 -> 23100 | E22: ='Caminho A — Trajetória'!E9/12 -> 23100 | F22: ='Caminho A — Trajetória'!F9/12 -> 21000 | G22: ='Caminho A — Trajetória'!G9/12 -> 24255 | H22: ='Caminho A — Trajetória'!H9/12 -> 25410 | I22: Limite: nível de outubro/2025 a março/2026
A24: LEITURA
A25: O SSF (Sistema de Sustentabilidade Financeira da CBF) entra em vigor em 1º de janeiro de 2026. Anos de transição (2026-2027) só geram advertências. Aplicação plena começa em 2028. O Vasco em 2025 já operaria acima do limite de 2028 (80%) na métrica de custos com elenco — folha ampliada + amortização sobre receita relevante chegou a 86%. Para conformidade, o caminho é o mesmo da competitividade financeira do Caminho A: cortar folha em proporção da receita. Regras especiais para clubes em RJ a partir de 30/04/2026: • Folha congelada na média dos últimos 6 meses • Janela de transferências com balanço zero ou positivo (capex ≤ venda atletas) • Acordo de reestruturação compatível com SSF Estas regras coincidem com o que o caminho A naturalmente exige. A disciplina forçada pelo SSF reforça o que o clube precisaria fazer de qualquer forma — apenas tira a margem de manobra para "voltar a contratar caro" quando o desempenho esportivo melhorar.
